<?xml version="1.0"?>

<robot xmlns:xacro="http://www.ros.org/wiki/xacro" name="gauss">
    <!-- properties -->
    <xacro:property name="base_joint1_z_distance" value="0.069" />
    <xacro:property name="joint1_joint2_z_distance" value="0.1815" />
    <xacro:property name="joint2_joint3_y_distance" value="0.185" />
    <xacro:property name="joint3_joint4_x_distance" value="0.149" />
    <xacro:property name="joint4_joint5_z_distance" value="0.101" /> 
    <xacro:property name="joint5_joint6_x_distance" value="0.026" /> 
    <xacro:property name="tcp_flange_x_distance" value="0.000" /> 

    <xacro:property name="PI" value="3.14159265359" />

    <xacro:property name="joint1_lower_limit" value="${-PI/2}" />
    <xacro:property name="joint1_upper_limit" value="${PI/2}" />
    <xacro:property name="joint2_lower_limit" value="${-PI/2}" />
    <xacro:property name="joint2_upper_limit" value="${PI/6}" />
    <xacro:property name="joint3_lower_limit" value="-0.26179938" />
    <xacro:property name="joint3_upper_limit" value="${PI/2}" />
    <xacro:property name="joint4_lower_limit" value="${-PI*2/3}" />
    <xacro:property name="joint4_upper_limit" value="${PI*2/3}" />
    <xacro:property name="joint5_lower_limit" value="-1.74532922" />
    <xacro:property name="joint5_upper_limit" value="1.74532922" />
    <xacro:property name="joint6_lower_limit" value="${-PI}" />
    <xacro:property name="joint6_upper_limit" value="${PI}" />

    <xacro:property name="gripper_mass" value="0.03" />
    <xacro:property name="finger_mass" value="0.01" />

    <!-- Import all Gazebo-customization elements, including Gazebo colors -->
    <xacro:include filename="$(find gauss_gazebo)/urdf/gauss.gazebo" />

    <!-- links -->
    <!-- Used for fixing robot to Gazebo 'base_link' -->
    <link name="world"/>

    <link name="base_link">
    	<inertial>
      	    <origin rpy="0 0 0" xyz="0 0 0"/>
      	    <mass value="1.0"/>
      	    <inertia ixx="1.0" ixy="0" ixz="0" iyy="1.0" iyz="0" izz="1.0"/>
    	</inertial>
        <visual>
            <origin xyz="0 0 0" rpy="0 0 0" />
            <geometry>
                <mesh filename="package://gauss_gazebo/meshes/base_link.dae" />
            </geometry>
            <material name="">
                <color rgba="0.2 0.6 1 1" />
            </material>
        </visual>
        <collision>
            <origin xyz="0 0 0" rpy="0 0 0" />
            <geometry>
                <mesh filename="package://gauss_gazebo/meshes/base_link.stl" />
            </geometry>
        </collision>
    </link>

    <link name="link1">
    	<inertial>
      	    <origin rpy="0 0 0" xyz="0 0 0"/>
      	    <mass value="1.0"/>
      	    <inertia ixx="1.0" ixy="0" ixz="0" iyy="1.0" iyz="0" izz="1.0"/>
    	</inertial>
        <visual>
            <origin xyz="0 0 0" rpy="0 0 0" />
            <geometry>
                <mesh filename="package://gauss_gazebo/meshes/link1.dae" />
            </geometry>
            <material name="">
                <color rgba="0.2 0.6 1 1" />
            </material>
        </visual>
        <collision>
            <origin xyz="0 0 0" rpy="0 0 0" />
            <geometry>
                <mesh filename="package://gauss_gazebo/meshes/link1.stl" />
            </geometry>
        </collision>
    </link>

    <link name="link2">
    	<inertial>
      	    <origin rpy="0 0 0" xyz="0 0 0"/>
      	    <mass value="1.0"/>
      	    <inertia ixx="1.0" ixy="0" ixz="0" iyy="1.0" iyz="0" izz="1.0"/>
    	</inertial>
        <visual>
            <origin xyz="0 0 0" rpy="0 0 0" />
            <geometry>
                <mesh filename="package://gauss_gazebo/meshes/link2.dae" />
            </geometry>
            <material name="">
                <color rgba="0.2 0.6 1 1" />
            </material>
        </visual>
        <collision>
            <origin xyz="0 0 0" rpy="0 0 0" />
            <geometry>
                <mesh filename="package://gauss_gazebo/meshes/link2.stl" />
            </geometry>
        </collision>
    </link>

    <link name="link3">
    	<inertial>
      	    <origin rpy="0 0 0" xyz="0 0 0"/>
      	    <mass value="0.6"/>
      	    <inertia ixx="1.0" ixy="0" ixz="0" iyy="1.0" iyz="0" izz="1.0"/>
    	</inertial>
        <visual>
            <origin xyz="0 0 0" rpy="0 0 0" />
            <geometry>
                <mesh filename="package://gauss_gazebo/meshes/link3.dae" />
            </geometry>
            <material name="">
                <color rgba="0.2 0.6 1 1" />
            </material>
        </visual>
        <collision>
            <origin xyz="0 0 0" rpy="0 0 0" />
            <geometry>
                <mesh filename="package://gauss_gazebo/meshes/link3.stl" />
            </geometry>
        </collision>
    </link>

    <link name="link4">
    	<inertial>
      	    <origin rpy="0 0 0" xyz="0 0 0"/>
      	    <mass value="0.4"/>
      	    <inertia ixx="1.0" ixy="0" ixz="0" iyy="1.0" iyz="0" izz="1.0"/>
    	</inertial>
        <visual>
            <origin xyz="0 0 0" rpy="0 0 0" />
            <geometry>
                <mesh filename="package://gauss_gazebo/meshes/link4.dae" />
            </geometry>
            <material name="">
                <color rgba="0.2 0.6 1 1" />
            </material>
        </visual>
        <collision>
            <origin xyz="0 0 0" rpy="0 0 0" />
            <geometry>
                <mesh filename="package://gauss_gazebo/meshes/link4.stl" />
            </geometry>
        </collision>
    </link>

    <link name="link5">
    	<inertial>
      	    <origin rpy="0 0 0" xyz="0 0 0"/>
      	    <mass value="0.2"/>
      	    <inertia ixx="1.0" ixy="0" ixz="0" iyy="1.0" iyz="0" izz="1.0"/>
    	</inertial>
        <visual>
            <origin xyz="0 0 0" rpy="0 0 0" />
            <geometry>
                <mesh filename="package://gauss_gazebo/meshes/link5.dae" />
            </geometry>
            <material name="">
                <color rgba="0.2 0.6 1 1" />
            </material>
        </visual>
        <collision>
            <origin xyz="0 0 0" rpy="0 0 0" />
            <geometry>
                <mesh filename="package://gauss_gazebo/meshes/link5.stl" />
            </geometry>
        </collision>
    </link>

    <link name="link6">
    	<inertial>
      	    <origin rpy="0 0 0" xyz="0 0 0"/>
      	    <mass value="0.1"/>
      	    <inertia ixx="1.0" ixy="0" ixz="0" iyy="1.0" iyz="0" izz="1.0"/>
    	</inertial>
        <visual>
            <origin xyz="0 0 0" rpy="0 0 0" />
            <geometry>
                <mesh filename="package://gauss_gazebo/meshes/link6.dae" />
            </geometry>
            <material name="">
                <color rgba="0.2 0.6 1 1" />
            </material>
        </visual>
        <collision>
            <origin xyz="0 0 0" rpy="0 0 0" />
            <geometry>
                <mesh filename="package://gauss_gazebo/meshes/link6.stl" />
            </geometry>
        </collision>
    </link>

    <link name="flange">

    </link>

    <link name="tcp">
        
    </link>

    <!-- joints -->
    <!-- Used for fixing robot to Gazebo 'base_link' -->
    <joint name="gazebo_fixed" type="fixed">
        <parent link="world" />
        <child link="base_link" />
        <origin xyz="0 0 0.7735" rpy="0 0 0" />
    </joint>

    <joint name="joint1" type="revolute">
        <parent link="base_link" />
        <child link="link1" />
        <origin xyz="0 0 ${base_joint1_z_distance}" rpy="0 0 0" />
        <axis xyz="0 0 1" />
        <dynamics damping="1.0" friction="4.0"/>
        <limit effort="50" velocity="0.5" lower="${joint1_lower_limit}" upper="${joint1_upper_limit}" />
    </joint>

    <joint name="joint2" type="revolute">
        <parent link="link1" />
        <child link="link2" />
        <origin xyz="0 0 ${joint1_joint2_z_distance}" rpy="${PI/2} 0 0" />
        <axis xyz="0 0 1" />
        <dynamics damping="1.0" friction="4.0"/>
        <limit effort="50" velocity="0.5" lower="${joint2_lower_limit}" upper="${joint2_upper_limit}" />
    </joint>

    <joint name="joint3" type="revolute">
        <parent link="link2" />
        <child link="link3" />
        <origin xyz="0 ${joint2_joint3_y_distance} 0" rpy="0 0 0" />
        <axis xyz="0 0 1" />
        <dynamics damping="1.0" friction="4.0"/>
        <limit effort="50" velocity="0.5" lower="${joint3_lower_limit}" upper="${joint3_upper_limit}" />
    </joint>

    <joint name="joint4" type="revolute">
        <parent link="link3" />
        <child link="link4" />
        <origin xyz="${joint3_joint4_x_distance} 0 0" rpy="0 ${PI/2} 0" />
        <axis xyz="0 0 1" />
        <dynamics damping="1.0" friction="3.0"/>
        <limit effort="50" velocity="0.5" lower="${joint4_lower_limit}" upper="${joint4_upper_limit}" />
    </joint>

    <joint name="joint5" type="revolute">
        <parent link="link4" />
        <child link="link5" />
        <origin xyz="0 0 ${joint4_joint5_z_distance}" rpy="0 ${-PI/2} 0" />
        <axis xyz="0 0 1" />
        <dynamics damping="1.0" friction="2.0"/>
        <limit effort="25" velocity="0.5" lower="${joint5_lower_limit}" upper="${joint5_upper_limit}" />
    </joint>

    <joint name="joint6" type="revolute">
        <parent link="link5" />
        <child link="link6" />
        <origin xyz="${joint5_joint6_x_distance} 0 0" rpy="0 ${PI/2} 0" />
        <axis xyz="0 0 1" />
        <dynamics damping="1.0" friction="2.0"/>
        <limit effort="25" velocity="0.5" lower="${joint6_lower_limit}" upper="${joint6_upper_limit}" />
    </joint>

    <joint name="joint_flange" type="fixed">
        <parent link="link6" />
        <child link="flange" />
        <origin xyz="0 0 0" rpy="0 ${-PI/2} ${-PI/2}" />
    </joint>

    <joint name="joint_tool" type="fixed">
        <parent link="flange" />
        <child link="tcp" />
	    <origin xyz="${tcp_flange_x_distance} 0 0" rpy="0 0 0" />
    </joint>

    <!-- tramsmissions -->
    <transmission name="joint1_transmission">
      <type>transmission_interface/SimpleTransmission</type>
      <joint name="joint1">
        <hardwareInterface>hardware_interface/EffortJointInterface</hardwareInterface>
      </joint>
      <actuator name="joint1_motor">
        <hardwareInterface>hardware_interface/EffortJointInterface</hardwareInterface>
        <mechanicalReduction>1</mechanicalReduction>
      </actuator>
    </transmission>

    <transmission name="joint2_transmission">
      <type>transmission_interface/SimpleTransmission</type>
      <joint name="joint2">
        <hardwareInterface>hardware_interface/EffortJointInterface</hardwareInterface>
      </joint>
      <actuator name="joint2_motor">
        <hardwareInterface>hardware_interface/EffortJointInterface</hardwareInterface>
        <mechanicalReduction>1</mechanicalReduction>
      </actuator>
    </transmission>

    <transmission name="joint3_transmission">
      <type>transmission_interface/SimpleTransmission</type>
      <joint name="joint3">
        <hardwareInterface>hardware_interface/EffortJointInterface</hardwareInterface>
      </joint>
      <actuator name="joint3_motor">
        <hardwareInterface>hardware_interface/EffortJointInterface</hardwareInterface>
        <mechanicalReduction>1</mechanicalReduction>
      </actuator>
    </transmission>

    <transmission name="joint4_transmission">
      <type>transmission_interface/SimpleTransmission</type>
      <joint name="joint4">
        <hardwareInterface>hardware_interface/EffortJointInterface</hardwareInterface>
      </joint>
      <actuator name="joint4_motor">
        <hardwareInterface>hardware_interface/EffortJointInterface</hardwareInterface>
        <mechanicalReduction>1</mechanicalReduction>
      </actuator>
    </transmission>

    <transmission name="joint5_transmission">
      <type>transmission_interface/SimpleTransmission</type>
      <joint name="joint5">
        <hardwareInterface>hardware_interface/EffortJointInterface</hardwareInterface>
      </joint>
      <actuator name="joint5_motor">
        <hardwareInterface>hardware_interface/EffortJointInterface</hardwareInterface>
        <mechanicalReduction>1</mechanicalReduction>
      </actuator>
    </transmission>

    <transmission name="joint6_transmission">
      <type>transmission_interface/SimpleTransmission</type>
      <joint name="joint6">
        <hardwareInterface>hardware_interface/EffortJointInterface</hardwareInterface>
      </joint>
      <actuator name="joint6_motor">
        <hardwareInterface>hardware_interface/EffortJointInterface</hardwareInterface>
        <mechanicalReduction>1</mechanicalReduction>
      </actuator>
    </transmission>

    <!--Two-finger gripper-->
    <link name="gripper_link">
      <inertial>
        <origin xyz="0 0 0" rpy="0 0 0"/>
        <mass value="${gripper_mass}"/>
      <inertia ixx="0.0001" ixy="0" ixz="0" iyy="0.0002" iyz="0" izz="0.0001"/>
      </inertial>
      <visual>
        <origin xyz="0 0 0" rpy="0 0 0"/>
        <geometry>
          <mesh filename="package://gauss_gazebo/meshes/gripper/gripper_base.dae"/>
        </geometry>
      </visual>
      <collision>
        <origin xyz="0 0 0" rpy="0 0 0"/>
        <geometry>
          <mesh filename="package://gauss_gazebo/meshes/gripper/gripper_base.dae"/>
        </geometry>
      </collision>
    </link>

    <link name="right_gripper_finger_link">
      <inertial>
        <origin xyz="0 0 0" rpy="0 0 0"/>
        <mass value="${finger_mass}"/>
        <inertia ixx="0.002" ixy="0" ixz="0" iyy="0.0002" iyz="0" izz="0.0002"/>
      </inertial>
      <visual>
        <origin xyz="0 0 0" rpy="0 0 0"/>
        <geometry>
          <mesh filename="package://gauss_gazebo/meshes/gripper/finger_right.dae"/>
        </geometry>
      </visual>
      <collision>
        <origin xyz="0 0 0" rpy="0 0 0"/>
        <geometry>
          <mesh filename="package://gauss_gazebo/meshes/gripper/finger_right_collision.dae"/>
        </geometry>
      </collision>
    </link>
    
    <link name="left_gripper_finger_link">
      <inertial>
        <origin xyz="0 0 0" rpy="0 0 0"/>
        <mass value="${finger_mass}"/>
        <inertia ixx="0.002" ixy="0" ixz="0" iyy="0.0002" iyz="0" izz="0.0002"/>
      </inertial>
      <visual>
        <origin xyz="0 0 0" rpy="0 0 0"/>
        <geometry>
          <mesh filename="package://gauss_gazebo/meshes/gripper/finger_left.dae"/>
        </geometry>
      </visual>
      <collision>
        <origin xyz="0 0 0" rpy="0 0 0"/>
        <geometry>
          <mesh filename="package://gauss_gazebo/meshes/gripper/finger_left_collision.dae"/>
        </geometry>
      </collision>
    </link>

    <joint name="right_gripper_finger_joint" type="prismatic">
      <origin rpy="0 0 0" xyz="0.028 -0.015 0" />
      <parent link="gripper_link" />
      <child link="right_gripper_finger_link" />
      <axis xyz="0 1 0" />
      <limit effort="15" lower="0.00" upper="0.01" velocity="0.01" />
      <dynamics damping="0.3" friction="0.2" />
    </joint>
    <joint name="left_gripper_finger_joint" type="prismatic">
      <origin rpy="0 0 0" xyz="0.028 0.015 0" />
      <parent link="gripper_link" />
      <child link="left_gripper_finger_link" />
      <axis xyz="0 -1 0" />
      <limit effort="15" lower="0.00" upper="0.01" velocity="0.01" />
      <dynamics damping="0.3" friction="0.2" />
    </joint>
    <joint name="gripper_joint" type="fixed">
      <parent link="tcp"/>
      <child link="gripper_link"/>
      <origin xyz="0.01 0 0" rpy="0 0 0"/>
      <axis xyz="0 1 0" />
    </joint>

    <transmission name="tran7">
        <type>transmission_interface/SimpleTransmission</type>
        <joint name="left_gripper_finger_joint">
          <hardwareInterface>hardware_interface/EffortJointInterface</hardwareInterface>
        </joint>
        <actuator name="motor7">
          <hardwareInterface>hardware_interface/EffortJointInterface</hardwareInterface>
          <mechanicalReduction>1</mechanicalReduction>
        </actuator>
    </transmission>

    <transmission name="tran8">
        <type>transmission_interface/SimpleTransmission</type>
        <joint name="right_gripper_finger_joint">
          <hardwareInterface>hardware_interface/EffortJointInterface</hardwareInterface>
        </joint>
        <actuator name="motor8">
          <hardwareInterface>hardware_interface/EffortJointInterface</hardwareInterface>
          <mechanicalReduction>1</mechanicalReduction>
        </actuator>
    </transmission>

</robot>
